<?xml version="1.0"?>
<sdf version="1.6">
    <model name="vehicle">
			<pose>
				0 0 0.325 0 -0 0
			</pose>
			<link name="chassis">
				<pose>
					-0.151427 -0 0.175 0 -0 0
				</pose>
				<inertial>
					<mass>
						1.14395
					</mass>
					<inertia>
						<ixx>
							0.126164
						</ixx>
						<ixy>
							0
						</ixy>
						<ixz>
							0
						</ixz>
						<iyy>
							0.416519
						</iyy>
						<iyz>
							0
						</iyz>
						<izz>
							0.481014
						</izz>
					</inertia>
				</inertial>
				<visual name="visual">
					<geometry>
						<box>
							<size>
								2.01142 1 0.568726
							</size>
						</box>
					</geometry>
				</visual>
				<collision name="collision">
					<geometry>
						<box>
							<size>
								2.01142 1 0.568726
							</size>
						</box>
					</geometry>
				</collision>
			</link>
			<link name="left_wheel">
				<pose>
					0.554283 0.625029 -0.025 -1.5707 0 0
				</pose>
				<inertial>
					<mass>
						2
					</mass>
					<inertia>
						<ixx>
							0.145833
						</ixx>
						<ixy>
							0
						</ixy>
						<ixz>
							0
						</ixz>
						<iyy>
							0.145833
						</iyy>
						<iyz>
							0
						</iyz>
						<izz>
							0.125
						</izz>
					</inertia>
				</inertial>
				<visual name="visual">
					<geometry>
						<sphere>
							<radius>
								0.3
							</radius>
						</sphere>
					</geometry>
				</visual>
				<collision name="collision">
					<geometry>
						<sphere>
							<radius>
								0.3
							</radius>
						</sphere>
					</geometry>
					<surface>
						<friction>
							<ode>
								<mu>
									1
								</mu>
								<mu2>
									1
								</mu2>
								<slip1>
									0
								</slip1>
								<slip2>
									0
								</slip2>
							</ode>
						</friction>
						<contact>
							<ode>
								<soft_cfm>
									0
								</soft_cfm>
								<soft_erp>
									0.2
								</soft_erp>
								<kp>
									1e+13
								</kp>
								<kd>
									1
								</kd>
								<max_vel>
									0.01
								</max_vel>
								<min_depth>
									0.01
								</min_depth>
							</ode>
						</contact>
					</surface>
				</collision>
			</link>
			<link name="right_wheel">
				<pose>
					0.554282 -0.625029 -0.025 -1.5707 0 0
				</pose>
				<inertial>
					<mass>
						2
					</mass>
					<inertia>
						<ixx>
							0.145833
						</ixx>
						<ixy>
							0
						</ixy>
						<ixz>
							0
						</ixz>
						<iyy>
							0.145833
						</iyy>
						<iyz>
							0
						</iyz>
						<izz>
							0.125
						</izz>
					</inertia>
				</inertial>
				<visual name="visual">
					<geometry>
						<sphere>
							<radius>
								0.3
							</radius>
						</sphere>
					</geometry>
				</visual>
				<collision name="collision">
					<geometry>
						<sphere>
							<radius>
								0.3
							</radius>
						</sphere>
					</geometry>
					<surface>
						<friction>
							<ode>
								<mu>
									1
								</mu>
								<mu2>
									1
								</mu2>
								<slip1>
									0
								</slip1>
								<slip2>
									0
								</slip2>
							</ode>
						</friction>
						<contact>
							<ode>
								<soft_cfm>
									0
								</soft_cfm>
								<soft_erp>
									0.2
								</soft_erp>
								<kp>
									1e+13
								</kp>
								<kd>
									1
								</kd>
								<max_vel>
									0.01
								</max_vel>
								<min_depth>
									0.01
								</min_depth>
							</ode>
						</contact>
					</surface>
				</collision>
			</link>
			<link name="caster">
				<pose>
					-0.957138 -0 -0.125 0 -0 0
				</pose>
				<inertial>
					<mass>
						1
					</mass>
					<inertia>
						<ixx>
							0.1
						</ixx>
						<ixy>
							0
						</ixy>
						<ixz>
							0
						</ixz>
						<iyy>
							0.1
						</iyy>
						<iyz>
							0
						</iyz>
						<izz>
							0.1
						</izz>
					</inertia>
				</inertial>
				<visual name="visual">
					<geometry>
						<sphere>
							<radius>
								0.2
							</radius>
						</sphere>
					</geometry>
				</visual>
				<collision name="collision">
					<geometry>
						<sphere>
							<radius>
								0.2
							</radius>
						</sphere>
					</geometry>
				</collision>
			</link>
			<link name="camera_link">
				<pose frame="">
					1 0 1 0 0.25 0
				</pose>
				<inertial>
					<inertia>
						<ixx>
							1
						</ixx>
						<ixy>
							0
						</ixy>
						<ixz>
							0
						</ixz>
						<iyy>
							1
						</iyy>
						<iyz>
							0
						</iyz>
						<izz>
							1
						</izz>
					</inertia>
					<mass>
						1.0
					</mass>
				</inertial>
				<collision name="my_collision">
					<pose>
						0 0 0.5 0 0 0
					</pose>
					<geometry>
						<box>
							<size>
								1 1 1
							</size>
						</box>
					</geometry>
				</collision>
				<visual name="my_visual">
					<geometry>
						<box>
							<size>
								0.005 0.005 0.005
							</size>
						</box>
					</geometry>
				</visual>
				<sensor type="camera" name="my_camera">
					<camera>
						<horizontal_fov>
							2.547
						</horizontal_fov>
						<image>
							<width>
								800
							</width>
							<height>
								600
							</height>
						</image>
						<clip>
							<near>
								0.01
							</near>
							<far>
								100
							</far>
						</clip>
					</camera>
					<always_on>
						1
					</always_on>
					<update_rate>
						10
					</update_rate>
					<visualize>
						true
					</visualize>
					<plugin name="camera_controller" filename="libgazebo_ros_camera.so">
						<alwaysOn>
							true
						</alwaysOn>
						<updateRate>
							0.0
						</updateRate>
						<cameraName>
							vehicle_camera
						</cameraName>
						<imageTopicName>
							image_raw
						</imageTopicName>
						<cameraInfoTopicName>
							camera_info
						</cameraInfoTopicName>
						<frameName>
							camera_link
						</frameName>
						<hackBaseline>
							0.07
						</hackBaseline>
						<distortionK1>
							0.0
						</distortionK1>
						<distortionK2>
							0.0
						</distortionK2>
						<distortionK3>
							0.0
						</distortionK3>
						<distortionT1>
							0.0
						</distortionT1>
						<distortionT2>
							0.0
						</distortionT2>
					</plugin>
				</sensor>
			</link>
			<joint name="camera_joint" type="fixed">
				<child>
					camera_link
				</child>
				<parent>
					chassis
				</parent>
			</joint>
			<joint name="left_wheel_joint" type="revolute">
				<parent>
					chassis
				</parent>
				<child>
					left_wheel
				</child>
				<axis>
					<xyz>
						0 0 1
					</xyz>
					<limit>
						<lower>
							-1.79769e+308
						</lower>
						<upper>
							1.79769e+308
						</upper>
					</limit>
				</axis>
			</joint>
			<joint name="right_wheel_joint" type="revolute">
				<parent>
					chassis
				</parent>
				<child>
					right_wheel
				</child>
				<axis>
					<xyz>
						0 0 1
					</xyz>
					<limit>
						<lower>
							-1.79769e+308
						</lower>
						<upper>
							1.79769e+308
						</upper>
					</limit>
				</axis>
			</joint>
			<joint name="caster_wheel" type="ball">
				<parent>
					chassis
				</parent>
				<child>
					caster
				</child>
			</joint>
			<plugin name="differential_drive_controller" filename="libgazebo_ros_diff_drive.so">
				<robotNamespace />
				<alwaysOn>
					true
				</alwaysOn>
				<updateRate>
					10
				</updateRate>
				<legacyMode>
					true
				</legacyMode>
				<leftJoint>
					left_wheel_joint
				</leftJoint>
				<rightJoint>
					right_wheel_joint
				</rightJoint>
				<wheelSeparation>
					0.5380
				</wheelSeparation>
				<wheelDiameter>
					0.2410
				</wheelDiameter>
				<torque>
					20
				</torque>
				<commandTopic>
					cmd_vel
				</commandTopic>
				<odometryTopic>
					odom
				</odometryTopic>
				<odometryFrame>
					odom
				</odometryFrame>
				<robotBaseFrame>
					chassis
				</robotBaseFrame>
				<publishWheelTF>
					false
				</publishWheelTF>
				<publishWheelJointState>
					false
				</publishWheelJointState>
				<rosDebugLevel>
					na
				</rosDebugLevel>
				<wheelAcceleration>
					0
				</wheelAcceleration>
				<wheelTorque>
					5
				</wheelTorque>
				<odometrySource>
					world
				</odometrySource>
				<publishTf>
					1
				</publishTf>
			</plugin>
		</model>
</sdf>
